2017-06-20 16:55:00,236 utilFunction.py[line:95] INFO HTTPSConnectionPool(host='www.baidu.com', port=443): Max retries exceeded with url: / (Caused by ConnectTimeoutError(<requests.packages.urllib3.connection.VerifiedHTTPSConnection object at 0x7fed241e5e90>, 'Connection to 139.255.92.5 timed out. (connect timeout=40)'))
2017-06-20 16:55:00,239 utilFunction.py[line:95] INFO HTTPSConnectionPool(host='www.baidu.com', port=443): Max retries exceeded with url: / (Caused by ConnectTimeoutError(<requests.packages.urllib3.connection.VerifiedHTTPSConnection object at 0x32eb0d0>, 'Connection to 139.255.92.5 timed out. (connect timeout=40)'))
2017-06-20 16:55:00,239 utilFunction.py[line:95] INFO HTTPSConnectionPool(host='www.baidu.com', port=443): Max retries exceeded with url: / (Caused by ConnectTimeoutError(<requests.packages.urllib3.connection.VerifiedHTTPSConnection object at 0x32e3750>, 'Connection to 139.255.92.5 timed out. (connect timeout=40)'))
2017-06-20 16:55:00,346 utilFunction.py[line:95] INFO HTTPSConnectionPool(host='www.baidu.com', port=443): Max retries exceeded with url: / (Caused by ConnectTimeoutError(<requests.packages.urllib3.connection.VerifiedHTTPSConnection object at 0x7fed081b29d0>, 'Connection to 139.255.92.5 timed out. (connect timeout=40)'))
2017-06-20 16:55:00,348 utilFunction.py[line:95] INFO HTTPSConnectionPool(host='www.baidu.com', port=443): Max retries exceeded with url: / (Caused by ConnectTimeoutError(<requests.packages.urllib3.connection.VerifiedHTTPSConnection object at 0x7fed081b2d50>, 'Connection to 139.255.92.5 timed out. (connect timeout=40)'))
2017-06-20 16:55:00,350 utilFunction.py[line:95] INFO HTTPSConnectionPool(host='www.baidu.com', port=443): Max retries exceeded with url: / (Caused by ConnectTimeoutError(<requests.packages.urllib3.connection.VerifiedHTTPSConnection object at 0x7fed2c193110>, 'Connection to 139.255.92.5 timed out. (connect timeout=40)'))
2017-06-20 16:55:00,370 utilFunction.py[line:95] INFO HTTPSConnectionPool(host='www.baidu.com', port=443): Max retries exceeded with url: / (Caused by ConnectTimeoutError(<requests.packages.urllib3.connection.VerifiedHTTPSConnection object at 0x7fed081b2c50>, 'Connection to 139.255.92.5 timed out. (connect timeout=40)'))
2017-06-20 16:55:00,450 utilFunction.py[line:95] INFO HTTPSConnectionPool(host='www.baidu.com', port=443): Max retries exceeded with url: / (Caused by ConnectTimeoutError(<requests.packages.urllib3.connection.VerifiedHTTPSConnection object at 0x7fed2c33f790>, 'Connection to 139.255.92.5 timed out. (connect timeout=40)'))
2017-06-20 16:55:00,464 utilFunction.py[line:95] INFO HTTPSConnectionPool(host='www.baidu.com', port=443): Max retries exceeded with url: / (Caused by ConnectTimeoutError(<requests.packages.urllib3.connection.VerifiedHTTPSConnection object at 0x7fed2c33fbd0>, 'Connection to 139.255.92.5 timed out. (connect timeout=40)'))
2017-06-20 16:55:00,470 utilFunction.py[line:95] INFO HTTPSConnectionPool(host='www.baidu.com', port=443): Max retries exceeded with url: / (Caused by ConnectTimeoutError(<requests.packages.urllib3.connection.VerifiedHTTPSConnection object at 0x7fed2c33fad0>, 'Connection to 139.255.92.5 timed out. (connect timeout=40)'))
2017-06-20 16:55:08,753 utilFunction.py[line:92] DEBUG 198.23.74.170:81 is ok
2017-06-20 16:55:09,602 utilFunction.py[line:95] INFO HTTPSConnectionPool(host='www.baidu.com', port=443): Max retries exceeded with url: / (Caused by ProxyError('Cannot connect to proxy.', error(104, 'Connection reset by peer')))
2017-06-20 16:55:09,627 utilFunction.py[line:92] DEBUG 198.23.74.170:81 is ok
2017-06-20 16:55:09,763 utilFunction.py[line:92] DEBUG 198.23.74.170:81 is ok
2017-06-20 16:55:10,174 utilFunction.py[line:95] INFO HTTPSConnectionPool(host='www.baidu.com', port=443): Max retries exceeded with url: / (Caused by ProxyError('Cannot connect to proxy.', error(104, 'Connection reset by peer')))
2017-06-20 16:55:11,094 utilFunction.py[line:95] INFO HTTPSConnectionPool(host='www.baidu.com', port=443): Max retries exceeded with url: / (Caused by ProxyError('Cannot connect to proxy.', error(104, 'Connection reset by peer')))
2017-06-20 16:55:11,487 utilFunction.py[line:92] DEBUG 198.23.74.170:81 is ok
2017-06-20 16:55:12,487 utilFunction.py[line:92] DEBUG 198.23.74.170:81 is ok
2017-06-20 16:55:12,836 utilFunction.py[line:92] DEBUG 198.23.74.170:81 is ok
2017-06-20 16:55:18,083 utilFunction.py[line:95] INFO HTTPSConnectionPool(host='www.baidu.com', port=443): Max retries exceeded with url: / (Caused by ProxyError('Cannot connect to proxy.', error(104, 'Connection reset by peer')))
2017-06-20 16:55:19,312 utilFunction.py[line:95] INFO HTTPSConnectionPool(host='www.baidu.com', port=443): Max retries exceeded with url: / (Caused by ProxyError('Cannot connect to proxy.', error(104, 'Connection reset by peer')))
2017-06-20 16:55:20,901 utilFunction.py[line:92] DEBUG 191.5.114.138:8080 is ok
2017-06-20 16:55:22,048 utilFunction.py[line:92] DEBUG 191.5.114.138:8080 is ok
2017-06-20 16:55:22,170 utilFunction.py[line:92] DEBUG 191.5.114.138:8080 is ok
2017-06-20 16:55:22,968 utilFunction.py[line:92] DEBUG 191.5.114.138:8080 is ok
2017-06-20 16:55:26,864 utilFunction.py[line:92] DEBUG 191.5.114.138:8080 is ok
2017-06-20 16:55:27,780 utilFunction.py[line:92] DEBUG 188.232.223.188:53281 is ok
2017-06-20 16:55:30,380 utilFunction.py[line:92] DEBUG 188.232.223.188:53281 is ok
2017-06-20 16:55:31,426 utilFunction.py[line:92] DEBUG 89.40.113.24:1189 is ok
2017-06-20 16:55:33,547 utilFunction.py[line:92] DEBUG 89.40.113.24:1189 is ok
2017-06-20 16:55:34,047 utilFunction.py[line:92] DEBUG 191.5.114.138:8080 is ok
2017-06-20 16:55:34,727 utilFunction.py[line:92] DEBUG 188.232.223.188:53281 is ok
2017-06-20 16:55:34,779 utilFunction.py[line:92] DEBUG 188.232.223.188:53281 is ok
2017-06-20 16:55:37,886 utilFunction.py[line:92] DEBUG 89.40.113.24:1189 is ok
2017-06-20 16:55:37,924 utilFunction.py[line:92] DEBUG 89.40.113.24:1189 is ok
2017-06-20 16:55:39,893 utilFunction.py[line:92] DEBUG 188.232.223.188:53281 is ok
2017-06-20 16:55:40,933 utilFunction.py[line:95] INFO HTTPSConnectionPool(host='www.baidu.com', port=443): Max retries exceeded with url: / (Caused by ProxyError('Cannot connect to proxy.', error(104, 'Connection reset by peer')))
2017-06-20 16:55:43,077 utilFunction.py[line:92] DEBUG 89.40.113.24:1189 is ok
2017-06-20 16:55:44,116 utilFunction.py[line:92] DEBUG 89.40.113.24:1189 is ok
2017-06-20 16:55:48,775 utilFunction.py[line:95] INFO HTTPSConnectionPool(host='www.baidu.com', port=443): Max retries exceeded with url: / (Caused by ConnectTimeoutError(<requests.packages.urllib3.connection.VerifiedHTTPSConnection object at 0x32eb190>, 'Connection to 191.5.114.138 timed out. (connect timeout=40)'))
2017-06-20 16:55:51,139 utilFunction.py[line:95] INFO HTTPSConnectionPool(host='www.baidu.com', port=443): Max retries exceeded with url: / (Caused by ConnectTimeoutError(<requests.packages.urllib3.connection.VerifiedHTTPSConnection object at 0x7fed2c33f310>, 'Connection to 191.5.114.138 timed out. (connect timeout=40)'))
2017-06-20 16:55:57,898 utilFunction.py[line:95] INFO HTTPSConnectionPool(host='www.baidu.com', port=443): Max retries exceeded with url: / (Caused by ProxyError('Cannot connect to proxy.', error(104, 'Connection reset by peer')))
2017-06-20 16:55:58,114 utilFunction.py[line:95] INFO HTTPSConnectionPool(host='www.baidu.com', port=443): Max retries exceeded with url: / (Caused by ConnectTimeoutError(<requests.packages.urllib3.connection.VerifiedHTTPSConnection object at 0x7fed2c33fcd0>, 'Connection to 191.5.114.138 timed out. (connect timeout=40)'))
2017-06-20 16:55:59,096 utilFunction.py[line:92] DEBUG 188.232.223.188:53281 is ok
2017-06-20 16:55:59,264 utilFunction.py[line:92] DEBUG 187.84.240.162:8080 is ok
2017-06-20 16:56:03,376 utilFunction.py[line:92] DEBUG 89.40.113.24:1189 is ok
2017-06-20 16:56:14,085 utilFunction.py[line:95] INFO HTTPSConnectionPool(host='www.baidu.com', port=443): Max retries exceeded with url: / (Caused by ConnectTimeoutError(<requests.packages.urllib3.connection.VerifiedHTTPSConnection object at 0x32e3d50>, 'Connection to 188.232.223.188 timed out. (connect timeout=40)'))
2017-06-20 16:56:17,517 utilFunction.py[line:92] DEBUG 89.40.113.24:1189 is ok
2017-06-20 16:56:17,898 utilFunction.py[line:95] INFO HTTPSConnectionPool(host='www.baidu.com', port=443): Max retries exceeded with url: / (Caused by ConnectTimeoutError(<requests.packages.urllib3.connection.VerifiedHTTPSConnection object at 0x7fed1819bb10>, 'Connection to 187.84.240.162 timed out. (connect timeout=40)'))
2017-06-20 16:56:17,965 utilFunction.py[line:95] INFO HTTPSConnectionPool(host='www.baidu.com', port=443): Max retries exceeded with url: / (Caused by ConnectTimeoutError(<requests.packages.urllib3.connection.VerifiedHTTPSConnection object at 0x7fed081b3750>, 'Connection to 187.84.240.162 timed out. (connect timeout=40)'))
2017-06-20 16:56:23,108 utilFunction.py[line:95] INFO HTTPSConnectionPool(host='www.baidu.com', port=443): Max retries exceeded with url: / (Caused by ConnectTimeoutError(<requests.packages.urllib3.connection.VerifiedHTTPSConnection object at 0x7fed081b3a90>, 'Connection to 187.84.240.162 timed out. (connect timeout=40)'))
2017-06-20 16:56:24,127 utilFunction.py[line:95] INFO HTTPSConnectionPool(host='www.baidu.com', port=443): Max retries exceeded with url: / (Caused by ConnectTimeoutError(<requests.packages.urllib3.connection.VerifiedHTTPSConnection object at 0x7fed081b3c50>, 'Connection to 187.84.240.162 timed out. (connect timeout=40)'))
2017-06-20 16:56:25,488 utilFunction.py[line:92] DEBUG 188.232.223.188:53281 is ok
2017-06-20 16:56:28,648 utilFunction.py[line:92] DEBUG 89.40.113.24:1189 is ok
2017-06-20 16:56:30,617 utilFunction.py[line:92] DEBUG 187.84.240.162:8080 is ok
2017-06-20 16:56:37,915 utilFunction.py[line:95] INFO HTTPSConnectionPool(host='www.baidu.com', port=443): Max retries exceeded with url: / (Caused by ConnectTimeoutError(<requests.packages.urllib3.connection.VerifiedHTTPSConnection object at 0x7fed1827a990>, 'Connection to 107.191.46.213 timed out. (connect timeout=40)'))
2017-06-20 16:56:38,348 utilFunction.py[line:95] INFO HTTPSConnectionPool(host='www.baidu.com', port=443): Max retries exceeded with url: / (Caused by ProxyError('Cannot connect to proxy.', NewConnectionError('<requests.packages.urllib3.connection.VerifiedHTTPSConnection object at 0x7fed2c33f190>: Failed to establish a new connection: [Errno 111] Connection refused',)))
2017-06-20 16:56:39,278 utilFunction.py[line:95] INFO HTTPSConnectionPool(host='www.baidu.com', port=443): Max retries exceeded with url: / (Caused by ConnectTimeoutError(<requests.packages.urllib3.connection.VerifiedHTTPSConnection object at 0x7fed081b36d0>, 'Connection to 107.191.46.213 timed out. (connect timeout=40)'))
2017-06-20 16:56:39,644 utilFunction.py[line:95] INFO HTTPSConnectionPool(host='www.baidu.com', port=443): Max retries exceeded with url: / (Caused by ProxyError('Cannot connect to proxy.', NewConnectionError('<requests.packages.urllib3.connection.VerifiedHTTPSConnection object at 0x7fed2c33f750>: Failed to establish a new connection: [Errno 111] Connection refused',)))
2017-06-20 16:56:44,608 utilFunction.py[line:92] DEBUG 187.84.240.162:8080 is ok
2017-06-20 16:56:48,113 utilFunction.py[line:92] DEBUG 180.158.218.58:9000 is ok
2017-06-20 16:56:50,091 utilFunction.py[line:95] INFO HTTPSConnectionPool(host='www.baidu.com', port=443): Max retries exceeded with url: / (Caused by ProxyError('Cannot connect to proxy.', error(104, 'Connection reset by peer')))
2017-06-20 16:56:51,324 utilFunction.py[line:92] DEBUG 180.158.218.58:9000 is ok
2017-06-20 16:56:53,198 utilFunction.py[line:92] DEBUG 89.40.113.24:1189 is ok
2017-06-20 16:56:57,930 utilFunction.py[line:95] INFO HTTPSConnectionPool(host='www.baidu.com', port=443): Max retries exceeded with url: / (Caused by ConnectTimeoutError(<requests.packages.urllib3.connection.VerifiedHTTPSConnection object at 0x7fed1819ba50>, 'Connection to 107.191.46.213 timed out. (connect timeout=40)'))
2017-06-20 16:56:57,979 utilFunction.py[line:95] INFO HTTPSConnectionPool(host='www.baidu.com', port=443): Max retries exceeded with url: / (Caused by ConnectTimeoutError(<requests.packages.urllib3.connection.VerifiedHTTPSConnection object at 0x7fed081b3750>, 'Connection to 107.191.46.213 timed out. (connect timeout=40)'))
2017-06-20 16:56:58,318 utilFunction.py[line:95] INFO HTTPSConnectionPool(host='www.baidu.com', port=443): Max retries exceeded with url: / (Caused by ProxyError('Cannot connect to proxy.', NewConnectionError('<requests.packages.urllib3.connection.VerifiedHTTPSConnection object at 0x7fed1819b790>: Failed to establish a new connection: [Errno 111] Connection refused',)))
2017-06-20 16:56:58,382 utilFunction.py[line:95] INFO HTTPSConnectionPool(host='www.baidu.com', port=443): Max retries exceeded with url: / (Caused by ProxyError('Cannot connect to proxy.', NewConnectionError('<requests.packages.urllib3.connection.VerifiedHTTPSConnection object at 0x32e3890>: Failed to establish a new connection: [Errno 111] Connection refused',)))
2017-06-20 16:57:00,646 utilFunction.py[line:92] DEBUG 108.61.229.123:8080 is ok
2017-06-20 16:57:01,267 utilFunction.py[line:92] DEBUG 187.84.240.162:8080 is ok
2017-06-20 16:57:03,156 utilFunction.py[line:95] INFO HTTPSConnectionPool(host='www.baidu.com', port=443): Max retries exceeded with url: / (Caused by ConnectTimeoutError(<requests.packages.urllib3.connection.VerifiedHTTPSConnection object at 0x7fed081b3b90>, 'Connection to 107.191.46.213 timed out. (connect timeout=40)'))
2017-06-20 16:57:03,542 utilFunction.py[line:95] INFO HTTPSConnectionPool(host='www.baidu.com', port=443): Max retries exceeded with url: / (Caused by ProxyError('Cannot connect to proxy.', NewConnectionError('<requests.packages.urllib3.connection.VerifiedHTTPSConnection object at 0x32e3e10>: Failed to establish a new connection: [Errno 111] Connection refused',)))
2017-06-20 16:57:04,158 utilFunction.py[line:95] INFO HTTPSConnectionPool(host='www.baidu.com', port=443): Max retries exceeded with url: / (Caused by ConnectTimeoutError(<requests.packages.urllib3.connection.VerifiedHTTPSConnection object at 0x7fed081b3950>, 'Connection to 107.191.46.213 timed out. (connect timeout=40)'))
2017-06-20 16:57:04,543 utilFunction.py[line:95] INFO HTTPSConnectionPool(host='www.baidu.com', port=443): Max retries exceeded with url: / (Caused by ProxyError('Cannot connect to proxy.', NewConnectionError('<requests.packages.urllib3.connection.VerifiedHTTPSConnection object at 0x7fed2c33f4d0>: Failed to establish a new connection: [Errno 111] Connection refused',)))
2017-06-20 16:57:05,937 utilFunction.py[line:92] DEBUG 180.158.218.58:9000 is ok
2017-06-20 16:57:06,044 utilFunction.py[line:92] DEBUG 180.158.218.58:9000 is ok
2017-06-20 16:57:09,080 utilFunction.py[line:92] DEBUG 85.172.60.112:80 is ok
2017-06-20 16:57:10,650 utilFunction.py[line:95] INFO HTTPSConnectionPool(host='www.baidu.com', port=443): Max retries exceeded with url: / (Caused by ConnectTimeoutError(<requests.packages.urllib3.connection.VerifiedHTTPSConnection object at 0x7fed2c33f6d0>, 'Connection to 107.191.46.213 timed out. (connect timeout=40)'))
2017-06-20 16:57:11,042 utilFunction.py[line:95] INFO HTTPSConnectionPool(host='www.baidu.com', port=443): Max retries exceeded with url: / (Caused by ProxyError('Cannot connect to proxy.', NewConnectionError('<requests.packages.urllib3.connection.VerifiedHTTPSConnection object at 0x7fed2c33f7d0>: Failed to establish a new connection: [Errno 111] Connection refused',)))
2017-06-20 16:57:14,879 utilFunction.py[line:92] DEBUG 108.61.229.123:8080 is ok
2017-06-20 16:57:14,884 utilFunction.py[line:92] DEBUG 187.84.240.162:8080 is ok
2017-06-20 16:57:15,097 utilFunction.py[line:92] DEBUG 180.158.218.58:9000 is ok
2017-06-20 16:57:18,553 utilFunction.py[line:92] DEBUG 180.158.218.58:9000 is ok
2017-06-20 16:57:24,628 utilFunction.py[line:95] INFO HTTPSConnectionPool(host='www.baidu.com', port=443): Max retries exceeded with url: / (Caused by ConnectTimeoutError(<requests.packages.urllib3.connection.VerifiedHTTPSConnection object at 0x7fed081b29d0>, 'Connection to 107.191.46.213 timed out. (connect timeout=40)'))
2017-06-20 16:57:25,406 utilFunction.py[line:95] INFO HTTPSConnectionPool(host='www.baidu.com', port=443): Max retries exceeded with url: / (Caused by ProxyError('Cannot connect to proxy.', NewConnectionError('<requests.packages.urllib3.connection.VerifiedHTTPSConnection object at 0x7fed081b2710>: Failed to establish a new connection: [Errno 111] Connection refused',)))
2017-06-20 16:59:12,012 utilFunction.py[line:111] INFO <urlopen error timed out>
2017-06-21 11:33:58,322 utilFunction.py[line:111] INFO [Errno 104] Connection reset by peer
2017-06-21 11:46:22,408 utilFunction.py[line:108] INFO HTTP Error 400: Bad Request
2017-06-21 12:03:26,812 utilFunction.py[line:111] INFO The read operation timed out
2017-06-21 14:24:05,341 utilFunction.py[line:111] INFO <urlopen error [Errno -2] Name or service not known>
2017-06-21 14:24:21,771 utilFunction.py[line:111] INFO <urlopen error [Errno -2] Name or service not known>
2017-06-21 14:34:08,492 utilFunction.py[line:92] DEBUG 82.99.213.214:8080 is ok
2017-06-21 14:34:08,591 utilFunction.py[line:92] DEBUG 82.99.213.214:8080 is ok
2017-06-21 14:34:10,927 utilFunction.py[line:92] DEBUG 82.99.213.214:8080 is ok
2017-06-21 14:34:12,444 utilFunction.py[line:92] DEBUG 82.99.213.214:8080 is ok
2017-06-21 14:34:12,803 utilFunction.py[line:95] INFO ('Connection aborted.', BadStatusLine("''",))
2017-06-21 14:34:20,369 utilFunction.py[line:92] DEBUG 103.10.169.100:3128 is ok
2017-06-21 14:34:20,874 utilFunction.py[line:92] DEBUG 103.10.169.100:3128 is ok
2017-06-21 14:34:42,433 utilFunction.py[line:95] INFO HTTPSConnectionPool(host='www.baidu.com', port=443): Max retries exceeded with url: / (Caused by ConnectTimeoutError(<requests.packages.urllib3.connection.VerifiedHTTPSConnection object at 0x7f17d41be5d0>, 'Connection to 82.99.213.214 timed out. (connect timeout=40)'))
2017-06-21 14:34:42,511 utilFunction.py[line:95] INFO HTTPSConnectionPool(host='www.baidu.com', port=443): Max retries exceeded with url: / (Caused by ConnectTimeoutError(<requests.packages.urllib3.connection.VerifiedHTTPSConnection object at 0x7f17cc2d53d0>, 'Connection to 82.99.213.214 timed out. (connect timeout=40)'))
2017-06-21 14:34:42,672 utilFunction.py[line:95] INFO HTTPSConnectionPool(host='www.baidu.com', port=443): Max retries exceeded with url: / (Caused by ConnectTimeoutError(<requests.packages.urllib3.connection.VerifiedHTTPSConnection object at 0x7f17d81f4b90>, 'Connection to 82.99.213.214 timed out. (connect timeout=40)'))
2017-06-21 14:34:42,673 utilFunction.py[line:95] INFO HTTPSConnectionPool(host='www.baidu.com', port=443): Max retries exceeded with url: / (Caused by ConnectTimeoutError(<requests.packages.urllib3.connection.VerifiedHTTPSConnection object at 0x7f17b4301c50>, 'Connection to 82.99.213.214 timed out. (connect timeout=40)'))
2017-06-21 14:34:42,703 utilFunction.py[line:95] INFO HTTPSConnectionPool(host='www.baidu.com', port=443): Max retries exceeded with url: / (Caused by ConnectTimeoutError(<requests.packages.urllib3.connection.VerifiedHTTPSConnection object at 0x7f17d81f4f50>, 'Connection to 82.99.213.214 timed out. (connect timeout=40)'))
2017-06-21 14:34:48,500 utilFunction.py[line:95] INFO HTTPSConnectionPool(host='www.baidu.com', port=443): Max retries exceeded with url: / (Caused by ConnectTimeoutError(<requests.packages.urllib3.connection.VerifiedHTTPSConnection object at 0x7f17d43154d0>, 'Connection to 103.10.169.100 timed out. (connect timeout=40)'))
2017-06-21 14:34:48,601 utilFunction.py[line:95] INFO HTTPSConnectionPool(host='www.baidu.com', port=443): Max retries exceeded with url: / (Caused by ConnectTimeoutError(<requests.packages.urllib3.connection.VerifiedHTTPSConnection object at 0x7f17d8277850>, 'Connection to 103.10.169.100 timed out. (connect timeout=40)'))
2017-06-21 14:34:52,484 utilFunction.py[line:95] INFO HTTPSConnectionPool(host='www.baidu.com', port=443): Max retries exceeded with url: / (Caused by ConnectTimeoutError(<requests.packages.urllib3.connection.VerifiedHTTPSConnection object at 0x7f17e0257590>, 'Connection to 103.10.169.100 timed out. (connect timeout=40)'))
2017-06-21 14:35:00,407 utilFunction.py[line:95] INFO HTTPSConnectionPool(host='www.baidu.com', port=443): Max retries exceeded with url: / (Caused by ConnectTimeoutError(<requests.packages.urllib3.connection.VerifiedHTTPSConnection object at 0x7f17cc1b9510>, 'Connection to 54.233.168.79 timed out. (connect timeout=40)'))
2017-06-21 14:35:47,529 utilFunction.py[line:92] DEBUG 190.121.158.114:8080 is ok
2017-06-21 14:35:47,547 utilFunction.py[line:92] DEBUG 190.121.158.114:8080 is ok
2017-06-21 14:35:48,017 utilFunction.py[line:92] DEBUG 190.121.158.114:8080 is ok
2017-06-21 14:35:49,046 utilFunction.py[line:95] INFO HTTPSConnectionPool(host='www.baidu.com', port=443): Max retries exceeded with url: / (Caused by ProxyError('Cannot connect to proxy.', error(104, 'Connection reset by peer')))
2017-06-21 14:35:49,139 utilFunction.py[line:95] INFO HTTPSConnectionPool(host='www.baidu.com', port=443): Max retries exceeded with url: / (Caused by ProxyError('Cannot connect to proxy.', error(104, 'Connection reset by peer')))
2017-06-21 14:35:49,139 utilFunction.py[line:95] INFO HTTPSConnectionPool(host='www.baidu.com', port=443): Max retries exceeded with url: / (Caused by ProxyError('Cannot connect to proxy.', error(104, 'Connection reset by peer')))
2017-06-21 14:35:49,223 utilFunction.py[line:95] INFO HTTPSConnectionPool(host='www.baidu.com', port=443): Max retries exceeded with url: / (Caused by ProxyError('Cannot connect to proxy.', error(104, 'Connection reset by peer')))
2017-06-21 14:35:57,569 utilFunction.py[line:95] INFO HTTPSConnectionPool(host='www.baidu.com', port=443): Max retries exceeded with url: / (Caused by ProxyError('Cannot connect to proxy.', error(104, 'Connection reset by peer')))
2017-06-21 14:36:13,224 utilFunction.py[line:95] INFO HTTPSConnectionPool(host='www.baidu.com', port=443): Max retries exceeded with url: / (Caused by ConnectTimeoutError(<requests.packages.urllib3.connection.VerifiedHTTPSConnection object at 0x7f86d82eee50>, 'Connection to 190.121.158.114 timed out. (connect timeout=40)'))
2017-06-21 14:36:13,351 utilFunction.py[line:95] INFO HTTPSConnectionPool(host='www.baidu.com', port=443): Max retries exceeded with url: / (Caused by ConnectTimeoutError(<requests.packages.urllib3.connection.VerifiedHTTPSConnection object at 0x7f86c41c5290>, 'Connection to 190.121.158.114 timed out. (connect timeout=40)'))
2017-06-21 14:36:13,352 utilFunction.py[line:95] INFO HTTPSConnectionPool(host='www.baidu.com', port=443): Max retries exceeded with url: / (Caused by ConnectTimeoutError(<requests.packages.urllib3.connection.VerifiedHTTPSConnection object at 0x7f86c41c5390>, 'Connection to 190.121.158.114 timed out. (connect timeout=40)'))
2017-06-21 14:36:29,189 utilFunction.py[line:95] INFO HTTPSConnectionPool(host='www.baidu.com', port=443): Max retries exceeded with url: / (Caused by ConnectTimeoutError(<requests.packages.urllib3.connection.VerifiedHTTPSConnection object at 0x7f86d813ee90>, 'Connection to 85.113.48.148 timed out. (connect timeout=40)'))
2017-06-21 14:36:29,192 utilFunction.py[line:95] INFO HTTPSConnectionPool(host='www.baidu.com', port=443): Max retries exceeded with url: / (Caused by ConnectTimeoutError(<requests.packages.urllib3.connection.VerifiedHTTPSConnection object at 0x7f86d813efd0>, 'Connection to 85.113.48.148 timed out. (connect timeout=40)'))
2017-06-21 14:36:29,269 utilFunction.py[line:95] INFO HTTPSConnectionPool(host='www.baidu.com', port=443): Max retries exceeded with url: / (Caused by ConnectTimeoutError(<requests.packages.urllib3.connection.VerifiedHTTPSConnection object at 0x7f86c41eb050>, 'Connection to 85.113.48.148 timed out. (connect timeout=40)'))
2017-06-21 14:36:31,374 utilFunction.py[line:92] DEBUG 85.113.48.148:8080 is ok
2017-06-21 14:36:31,380 utilFunction.py[line:92] DEBUG 85.113.48.148:8080 is ok
2017-06-21 14:36:31,387 utilFunction.py[line:92] DEBUG 85.113.48.148:8080 is ok
2017-06-21 14:36:37,757 utilFunction.py[line:92] DEBUG 85.113.48.148:8080 is ok
2017-06-21 14:36:40,233 utilFunction.py[line:95] INFO HTTPSConnectionPool(host='www.baidu.com', port=443): Max retries exceeded with url: / (Caused by ProxyError('Cannot connect to proxy.', error(104, 'Connection reset by peer')))
2017-06-21 14:37:08,642 utilFunction.py[line:95] INFO HTTPSConnectionPool(host='www.baidu.com', port=443): Max retries exceeded with url: / (Caused by ConnectTimeoutError(<requests.packages.urllib3.connection.VerifiedHTTPSConnection object at 0x7f86c41eb450>, 'Connection to 182.88.162.63 timed out. (connect timeout=40)'))
2017-06-21 14:37:08,652 utilFunction.py[line:95] INFO HTTPSConnectionPool(host='www.baidu.com', port=443): Max retries exceeded with url: / (Caused by ConnectTimeoutError(<requests.packages.urllib3.connection.VerifiedHTTPSConnection object at 0x7f86d82eeb10>, 'Connection to 85.113.48.148 timed out. (connect timeout=40)'))
2017-06-21 14:37:08,714 utilFunction.py[line:95] INFO HTTPSConnectionPool(host='www.baidu.com', port=443): Max retries exceeded with url: / (Caused by ProxyError('Cannot connect to proxy.', NewConnectionError('<requests.packages.urllib3.connection.VerifiedHTTPSConnection object at 0x7f86c41eb390>: Failed to establish a new connection: [Errno 111] Connection refused',)))
2017-06-21 14:37:09,205 utilFunction.py[line:95] INFO HTTPSConnectionPool(host='www.baidu.com', port=443): Max retries exceeded with url: / (Caused by ConnectTimeoutError(<requests.packages.urllib3.connection.VerifiedHTTPSConnection object at 0x7f86d813e290>, 'Connection to 182.88.162.63 timed out. (connect timeout=40)'))
2017-06-21 14:37:09,234 utilFunction.py[line:95] INFO HTTPSConnectionPool(host='www.baidu.com', port=443): Max retries exceeded with url: / (Caused by ConnectTimeoutError(<requests.packages.urllib3.connection.VerifiedHTTPSConnection object at 0x7f86d813e310>, 'Connection to 182.88.162.63 timed out. (connect timeout=40)'))
2017-06-21 14:37:09,272 utilFunction.py[line:95] INFO HTTPSConnectionPool(host='www.baidu.com', port=443): Max retries exceeded with url: / (Caused by ProxyError('Cannot connect to proxy.', NewConnectionError('<requests.packages.urllib3.connection.VerifiedHTTPSConnection object at 0x7f86d8233990>: Failed to establish a new connection: [Errno 111] Connection refused',)))
2017-06-21 14:37:09,298 utilFunction.py[line:95] INFO HTTPSConnectionPool(host='www.baidu.com', port=443): Max retries exceeded with url: / (Caused by ConnectTimeoutError(<requests.packages.urllib3.connection.VerifiedHTTPSConnection object at 0x7f86c41eb090>, 'Connection to 182.88.162.63 timed out. (connect timeout=40)'))
2017-06-21 14:37:09,303 utilFunction.py[line:95] INFO HTTPSConnectionPool(host='www.baidu.com', port=443): Max retries exceeded with url: / (Caused by ProxyError('Cannot connect to proxy.', NewConnectionError('<requests.packages.urllib3.connection.VerifiedHTTPSConnection object at 0x7f86d813e110>: Failed to establish a new connection: [Errno 111] Connection refused',)))
2017-06-21 14:37:09,362 utilFunction.py[line:95] INFO HTTPSConnectionPool(host='www.baidu.com', port=443): Max retries exceeded with url: / (Caused by ProxyError('Cannot connect to proxy.', NewConnectionError('<requests.packages.urllib3.connection.VerifiedHTTPSConnection object at 0x288a7d0>: Failed to establish a new connection: [Errno 111] Connection refused',)))
2017-06-21 14:37:11,414 utilFunction.py[line:95] INFO HTTPSConnectionPool(host='www.baidu.com', port=443): Max retries exceeded with url: / (Caused by ConnectTimeoutError(<requests.packages.urllib3.connection.VerifiedHTTPSConnection object at 0x7f86c41eb810>, 'Connection to 182.88.162.63 timed out. (connect timeout=40)'))
2017-06-21 14:37:11,423 utilFunction.py[line:95] INFO HTTPSConnectionPool(host='www.baidu.com', port=443): Max retries exceeded with url: / (Caused by ConnectTimeoutError(<requests.packages.urllib3.connection.VerifiedHTTPSConnection object at 0x7f86d813ed50>, 'Connection to 182.88.162.63 timed out. (connect timeout=40)'))
2017-06-21 14:37:11,429 utilFunction.py[line:95] INFO HTTPSConnectionPool(host='www.baidu.com', port=443): Max retries exceeded with url: / (Caused by ConnectTimeoutError(<requests.packages.urllib3.connection.VerifiedHTTPSConnection object at 0x7f86d813ed10>, 'Connection to 182.88.162.63 timed out. (connect timeout=40)'))
2017-06-21 14:37:11,478 utilFunction.py[line:95] INFO HTTPSConnectionPool(host='www.baidu.com', port=443): Max retries exceeded with url: / (Caused by ProxyError('Cannot connect to proxy.', NewConnectionError('<requests.packages.urllib3.connection.VerifiedHTTPSConnection object at 0x7f86c41eb790>: Failed to establish a new connection: [Errno 111] Connection refused',)))
2017-06-21 14:37:11,493 utilFunction.py[line:95] INFO HTTPSConnectionPool(host='www.baidu.com', port=443): Max retries exceeded with url: / (Caused by ProxyError('Cannot connect to proxy.', NewConnectionError('<requests.packages.urllib3.connection.VerifiedHTTPSConnection object at 0x288a390>: Failed to establish a new connection: [Errno 111] Connection refused',)))
2017-06-21 14:37:11,502 utilFunction.py[line:95] INFO HTTPSConnectionPool(host='www.baidu.com', port=443): Max retries exceeded with url: / (Caused by ProxyError('Cannot connect to proxy.', NewConnectionError('<requests.packages.urllib3.connection.VerifiedHTTPSConnection object at 0x7f86cc16ca90>: Failed to establish a new connection: [Errno 111] Connection refused',)))
2017-06-21 14:37:17,778 utilFunction.py[line:95] INFO HTTPSConnectionPool(host='www.baidu.com', port=443): Max retries exceeded with url: / (Caused by ConnectTimeoutError(<requests.packages.urllib3.connection.VerifiedHTTPSConnection object at 0x7f86cc270790>, 'Connection to 182.88.162.63 timed out. (connect timeout=40)'))
2017-06-21 14:37:17,841 utilFunction.py[line:95] INFO HTTPSConnectionPool(host='www.baidu.com', port=443): Max retries exceeded with url: / (Caused by ProxyError('Cannot connect to proxy.', NewConnectionError('<requests.packages.urllib3.connection.VerifiedHTTPSConnection object at 0x7f86cc270a90>: Failed to establish a new connection: [Errno 111] Connection refused',)))
2017-06-21 14:37:20,281 utilFunction.py[line:95] INFO HTTPSConnectionPool(host='www.baidu.com', port=443): Max retries exceeded with url: / (Caused by ConnectTimeoutError(<requests.packages.urllib3.connection.VerifiedHTTPSConnection object at 0x7f86c42aa710>, 'Connection to 182.88.162.63 timed out. (connect timeout=40)'))
2017-06-21 14:37:20,342 utilFunction.py[line:95] INFO HTTPSConnectionPool(host='www.baidu.com', port=443): Max retries exceeded with url: / (Caused by ProxyError('Cannot connect to proxy.', NewConnectionError('<requests.packages.urllib3.connection.VerifiedHTTPSConnection object at 0x7f86c42aa9d0>: Failed to establish a new connection: [Errno 111] Connection refused',)))
2017-06-21 14:39:14,525 utilFunction.py[line:108] INFO HTTP Error 404: Not Found
2017-06-21 14:42:40,363 utilFunction.py[line:95] INFO HTTPSConnectionPool(host='www.baidu.com', port=443): Max retries exceeded with url: / (Caused by ConnectTimeoutError(<requests.packages.urllib3.connection.VerifiedHTTPSConnection object at 0x7f7948224bd0>, 'Connection to 139.255.92.5 timed out. (connect timeout=40)'))
2017-06-21 14:42:40,468 utilFunction.py[line:95] INFO HTTPSConnectionPool(host='www.baidu.com', port=443): Max retries exceeded with url: / (Caused by ConnectTimeoutError(<requests.packages.urllib3.connection.VerifiedHTTPSConnection object at 0x7f79202a9890>, 'Connection to 139.255.92.5 timed out. (connect timeout=40)'))
2017-06-21 14:42:40,524 utilFunction.py[line:95] INFO HTTPSConnectionPool(host='www.baidu.com', port=443): Max retries exceeded with url: / (Caused by ConnectTimeoutError(<requests.packages.urllib3.connection.VerifiedHTTPSConnection object at 0x7f7940239850>, 'Connection to 139.255.92.5 timed out. (connect timeout=40)'))
2017-06-21 14:42:40,591 utilFunction.py[line:95] INFO HTTPSConnectionPool(host='www.baidu.com', port=443): Max retries exceeded with url: / (Caused by ConnectTimeoutError(<requests.packages.urllib3.connection.VerifiedHTTPSConnection object at 0x7f79401b0550>, 'Connection to 139.255.92.5 timed out. (connect timeout=40)'))
2017-06-21 14:42:40,599 utilFunction.py[line:95] INFO HTTPSConnectionPool(host='www.baidu.com', port=443): Max retries exceeded with url: / (Caused by ConnectTimeoutError(<requests.packages.urllib3.connection.VerifiedHTTPSConnection object at 0x7f79282329d0>, 'Connection to 139.255.92.5 timed out. (connect timeout=40)'))
2017-06-21 14:42:40,654 utilFunction.py[line:95] INFO HTTPSConnectionPool(host='www.baidu.com', port=443): Max retries exceeded with url: / (Caused by ConnectTimeoutError(<requests.packages.urllib3.connection.VerifiedHTTPSConnection object at 0x7f79281378d0>, 'Connection to 139.255.92.5 timed out. (connect timeout=40)'))
2017-06-21 14:42:40,686 utilFunction.py[line:95] INFO HTTPSConnectionPool(host='www.baidu.com', port=443): Max retries exceeded with url: / (Caused by ConnectTimeoutError(<requests.packages.urllib3.connection.VerifiedHTTPSConnection object at 0x7f79481edb10>, 'Connection to 139.255.92.5 timed out. (connect timeout=40)'))
2017-06-21 14:42:40,687 utilFunction.py[line:95] INFO HTTPSConnectionPool(host='www.baidu.com', port=443): Max retries exceeded with url: / (Caused by ConnectTimeoutError(<requests.packages.urllib3.connection.VerifiedHTTPSConnection object at 0x3369b10>, 'Connection to 139.255.92.5 timed out. (connect timeout=40)'))
2017-06-21 14:42:40,700 utilFunction.py[line:95] INFO HTTPSConnectionPool(host='www.baidu.com', port=443): Max retries exceeded with url: / (Caused by ConnectTimeoutError(<requests.packages.urllib3.connection.VerifiedHTTPSConnection object at 0x33699d0>, 'Connection to 139.255.92.5 timed out. (connect timeout=40)'))
2017-06-21 14:42:40,702 utilFunction.py[line:95] INFO HTTPSConnectionPool(host='www.baidu.com', port=443): Max retries exceeded with url: / (Caused by ConnectTimeoutError(<requests.packages.urllib3.connection.VerifiedHTTPSConnection object at 0x3369910>, 'Connection to 139.255.92.5 timed out. (connect timeout=40)'))
2017-06-21 14:42:48,079 utilFunction.py[line:92] DEBUG 198.23.74.170:81 is ok
2017-06-21 14:42:48,326 utilFunction.py[line:92] DEBUG 198.23.74.170:81 is ok
2017-06-21 14:42:49,593 utilFunction.py[line:108] INFO HTTP Error 404: Not Found
2017-06-21 14:42:49,933 utilFunction.py[line:92] DEBUG 198.23.74.170:81 is ok
2017-06-21 14:42:51,236 utilFunction.py[line:92] DEBUG 198.23.74.170:81 is ok
2017-06-21 14:42:51,496 utilFunction.py[line:92] DEBUG 198.23.74.170:81 is ok
2017-06-21 14:42:51,577 utilFunction.py[line:92] DEBUG 198.23.74.170:81 is ok
2017-06-21 14:42:53,792 utilFunction.py[line:95] INFO HTTPSConnectionPool(host='www.baidu.com', port=443): Max retries exceeded with url: / (Caused by ProxyError('Cannot connect to proxy.', error(104, 'Connection reset by peer')))
2017-06-21 14:43:01,784 utilFunction.py[line:95] INFO HTTPSConnectionPool(host='www.baidu.com', port=443): Max retries exceeded with url: / (Caused by ProxyError('Cannot connect to proxy.', error(104, 'Connection reset by peer')))
2017-06-21 14:43:02,292 utilFunction.py[line:95] INFO HTTPSConnectionPool(host='www.baidu.com', port=443): Max retries exceeded with url: / (Caused by ProxyError('Cannot connect to proxy.', NewConnectionError('<requests.packages.urllib3.connection.VerifiedHTTPSConnection object at 0x7f79401bc710>: Failed to establish a new connection: [Errno 111] Connection refused',)))
2017-06-21 14:43:08,042 utilFunction.py[line:92] DEBUG 191.5.114.138:8080 is ok
2017-06-21 14:43:08,172 utilFunction.py[line:95] INFO HTTPSConnectionPool(host='www.baidu.com', port=443): Max retries exceeded with url: / (Caused by ProxyError('Cannot connect to proxy.', NewConnectionError('<requests.packages.urllib3.connection.VerifiedHTTPSConnection object at 0x7f79401bc9d0>: Failed to establish a new connection: [Errno 111] Connection refused',)))
2017-06-21 14:43:09,868 utilFunction.py[line:95] INFO HTTPSConnectionPool(host='www.baidu.com', port=443): Max retries exceeded with url: / (Caused by ProxyError('Cannot connect to proxy.', error(104, 'Connection reset by peer')))
2017-06-21 14:43:10,002 utilFunction.py[line:95] INFO HTTPSConnectionPool(host='www.baidu.com', port=443): Max retries exceeded with url: / (Caused by ProxyError('Cannot connect to proxy.', NewConnectionError('<requests.packages.urllib3.connection.VerifiedHTTPSConnection object at 0x7f79481ed790>: Failed to establish a new connection: [Errno 111] Connection refused',)))
2017-06-21 14:43:11,664 utilFunction.py[line:95] INFO HTTPSConnectionPool(host='www.baidu.com', port=443): Max retries exceeded with url: / (Caused by ProxyError('Cannot connect to proxy.', error(104, 'Connection reset by peer')))
2017-06-21 14:43:11,792 utilFunction.py[line:95] INFO HTTPSConnectionPool(host='www.baidu.com', port=443): Max retries exceeded with url: / (Caused by ProxyError('Cannot connect to proxy.', NewConnectionError('<requests.packages.urllib3.connection.VerifiedHTTPSConnection object at 0x3369690>: Failed to establish a new connection: [Errno 111] Connection refused',)))
2017-06-21 14:43:13,022 utilFunction.py[line:108] INFO HTTP Error 404: Not Found
2017-06-21 14:43:14,078 utilFunction.py[line:92] DEBUG 188.232.223.188:53281 is ok
2017-06-21 14:43:17,257 utilFunction.py[line:92] DEBUG 89.40.113.24:1189 is ok
2017-06-21 14:43:19,058 utilFunction.py[line:92] DEBUG 188.232.223.188:53281 is ok
2017-06-21 14:43:19,765 utilFunction.py[line:92] DEBUG 198.23.74.170:81 is ok
2017-06-21 14:43:19,882 utilFunction.py[line:92] DEBUG 198.23.74.170:81 is ok
2017-06-21 14:43:20,124 utilFunction.py[line:92] DEBUG 188.232.223.188:53281 is ok
2017-06-21 14:43:20,512 utilFunction.py[line:95] INFO HTTPSConnectionPool(host='www.baidu.com', port=443): Max retries exceeded with url: / (Caused by ConnectTimeoutError(<requests.packages.urllib3.connection.VerifiedHTTPSConnection object at 0x7f7948224810>, 'Connection to 198.23.74.170 timed out. (connect timeout=40)'))
2017-06-21 14:43:22,107 utilFunction.py[line:92] DEBUG 89.40.113.24:1189 is ok
2017-06-21 14:43:23,297 utilFunction.py[line:92] DEBUG 89.40.113.24:1189 is ok
2017-06-21 14:43:26,647 utilFunction.py[line:92] DEBUG 188.232.223.188:53281 is ok
2017-06-21 14:43:28,339 utilFunction.py[line:95] INFO HTTPSConnectionPool(host='www.baidu.com', port=443): Max retries exceeded with url: / (Caused by ConnectTimeoutError(<requests.packages.urllib3.connection.VerifiedHTTPSConnection object at 0x7f79481edc50>, 'Connection to 191.5.114.138 timed out. (connect timeout=40)'))
2017-06-21 14:43:28,472 utilFunction.py[line:95] INFO HTTPSConnectionPool(host='www.baidu.com', port=443): Max retries exceeded with url: / (Caused by ProxyError('Cannot connect to proxy.', NewConnectionError('<requests.packages.urllib3.connection.VerifiedHTTPSConnection object at 0x7f79481edad0>: Failed to establish a new connection: [Errno 111] Connection refused',)))
2017-06-21 14:43:29,846 utilFunction.py[line:92] DEBUG 89.40.113.24:1189 is ok
2017-06-21 14:43:29,970 utilFunction.py[line:95] INFO HTTPSConnectionPool(host='www.baidu.com', port=443): Max retries exceeded with url: / (Caused by ConnectTimeoutError(<requests.packages.urllib3.connection.VerifiedHTTPSConnection object at 0x7f79202a98d0>, 'Connection to 191.5.114.138 timed out. (connect timeout=40)'))
2017-06-21 14:43:30,102 utilFunction.py[line:95] INFO HTTPSConnectionPool(host='www.baidu.com', port=443): Max retries exceeded with url: / (Caused by ProxyError('Cannot connect to proxy.', NewConnectionError('<requests.packages.urllib3.connection.VerifiedHTTPSConnection object at 0x7f79202a9a90>: Failed to establish a new connection: [Errno 111] Connection refused',)))
2017-06-21 14:43:31,297 utilFunction.py[line:92] DEBUG 191.5.114.138:8080 is ok
2017-06-21 14:43:31,422 utilFunction.py[line:95] INFO HTTPSConnectionPool(host='www.baidu.com', port=443): Max retries exceeded with url: / (Caused by ProxyError('Cannot connect to proxy.', NewConnectionError('<requests.packages.urllib3.connection.VerifiedHTTPSConnection object at 0x7f7948224c90>: Failed to establish a new connection: [Errno 111] Connection refused',)))
2017-06-21 14:43:32,248 utilFunction.py[line:92] DEBUG 191.5.114.138:8080 is ok
2017-06-21 14:43:32,376 utilFunction.py[line:95] INFO HTTPSConnectionPool(host='www.baidu.com', port=443): Max retries exceeded with url: / (Caused by ProxyError('Cannot connect to proxy.', NewConnectionError('<requests.packages.urllib3.connection.VerifiedHTTPSConnection object at 0x3369810>: Failed to establish a new connection: [Errno 111] Connection refused',)))
2017-06-21 14:43:33,291 utilFunction.py[line:95] INFO HTTPSConnectionPool(host='www.baidu.com', port=443): Max retries exceeded with url: / (Caused by ProxyError('Cannot connect to proxy.', error(104, 'Connection reset by peer')))
2017-06-21 14:43:38,208 utilFunction.py[line:92] DEBUG 188.232.223.188:53281 is ok
2017-06-21 14:43:38,861 utilFunction.py[line:108] INFO HTTP Error 404: Not Found
2017-06-21 14:43:38,882 utilFunction.py[line:95] INFO HTTPSConnectionPool(host='www.baidu.com', port=443): Max retries exceeded with url: / (Caused by ProxyError('Cannot connect to proxy.', error(104, 'Connection reset by peer')))
2017-06-21 14:43:38,973 utilFunction.py[line:92] DEBUG 187.84.240.162:8080 is ok
2017-06-21 14:43:41,252 utilFunction.py[line:95] INFO HTTPSConnectionPool(host='www.baidu.com', port=443): Max retries exceeded with url: / (Caused by ProxyError('Cannot connect to proxy.', error(104, 'Connection reset by peer')))
2017-06-21 14:43:41,387 utilFunction.py[line:95] INFO HTTPSConnectionPool(host='www.baidu.com', port=443): Max retries exceeded with url: / (Caused by ProxyError('Cannot connect to proxy.', NewConnectionError('<requests.packages.urllib3.connection.VerifiedHTTPSConnection object at 0x7f7940239190>: Failed to establish a new connection: [Errno 111] Connection refused',)))
2017-06-21 14:43:41,390 utilFunction.py[line:92] DEBUG 89.40.113.24:1189 is ok
2017-06-21 14:43:47,242 utilFunction.py[line:95] INFO HTTPSConnectionPool(host='www.baidu.com', port=443): Max retries exceeded with url: / (Caused by ProxyError('Cannot connect to proxy.', error(104, 'Connection reset by peer')))
2017-06-21 14:43:49,872 utilFunction.py[line:92] DEBUG 188.232.223.188:53281 is ok
2017-06-21 14:43:51,421 utilFunction.py[line:95] INFO HTTPSConnectionPool(host='www.baidu.com', port=443): Max retries exceeded with url: / (Caused by ProxyError('Cannot connect to proxy.', error(104, 'Connection reset by peer')))
2017-06-21 14:43:52,956 utilFunction.py[line:92] DEBUG 89.40.113.24:1189 is ok
2017-06-21 14:43:54,985 utilFunction.py[line:92] DEBUG 89.40.113.24:1189 is ok
2017-06-21 14:43:56,912 utilFunction.py[line:95] INFO HTTPSConnectionPool(host='www.baidu.com', port=443): Max retries exceeded with url: / (Caused by ProxyError('Cannot connect to proxy.', error(104, 'Connection reset by peer')))
2017-06-21 14:43:57,052 utilFunction.py[line:95] INFO HTTPSConnectionPool(host='www.baidu.com', port=443): Max retries exceeded with url: / (Caused by ProxyError('Cannot connect to proxy.', NewConnectionError('<requests.packages.urllib3.connection.VerifiedHTTPSConnection object at 0x7f7940239550>: Failed to establish a new connection: [Errno 111] Connection refused',)))
2017-06-21 14:44:06,849 utilFunction.py[line:95] INFO HTTPSConnectionPool(host='www.baidu.com', port=443): Max retries exceeded with url: / (Caused by ProxyError('Cannot connect to proxy.', error(104, 'Connection reset by peer')))
2017-06-21 14:44:09,283 utilFunction.py[line:92] DEBUG 188.232.223.188:53281 is ok
2017-06-21 14:44:10,007 utilFunction.py[line:92] DEBUG 89.40.113.24:1189 is ok
2017-06-21 14:44:10,149 utilFunction.py[line:95] INFO HTTPSConnectionPool(host='www.baidu.com', port=443): Max retries exceeded with url: / (Caused by ConnectTimeoutError(<requests.packages.urllib3.connection.VerifiedHTTPSConnection object at 0x7f79202a9950>, 'Connection to 188.232.223.188 timed out. (connect timeout=40)'))
2017-06-21 14:44:12,558 utilFunction.py[line:92] DEBUG 89.40.113.24:1189 is ok
2017-06-21 14:44:13,336 utilFunction.py[line:95] INFO HTTPSConnectionPool(host='www.baidu.com', port=443): Max retries exceeded with url: / (Caused by ConnectTimeoutError(<requests.packages.urllib3.connection.VerifiedHTTPSConnection object at 0x7f79401bc8d0>, 'Connection to 107.191.46.213 timed out. (connect timeout=40)'))
2017-06-21 14:44:13,722 utilFunction.py[line:92] DEBUG 89.40.113.24:1189 is ok
2017-06-21 14:44:16,374 utilFunction.py[line:92] DEBUG 187.84.240.162:8080 is ok
2017-06-21 14:44:18,902 utilFunction.py[line:95] INFO HTTPSConnectionPool(host='www.baidu.com', port=443): Max retries exceeded with url: / (Caused by ConnectTimeoutError(<requests.packages.urllib3.connection.VerifiedHTTPSConnection object at 0x7f79401bcd90>, 'Connection to 107.191.46.213 timed out. (connect timeout=40)'))
2017-06-21 14:44:19,001 utilFunction.py[line:95] INFO HTTPSConnectionPool(host='www.baidu.com', port=443): Max retries exceeded with url: / (Caused by ConnectTimeoutError(<requests.packages.urllib3.connection.VerifiedHTTPSConnection object at 0x7f79401bcdd0>, 'Connection to 107.191.46.213 timed out. (connect timeout=40)'))
2017-06-21 14:44:27,275 utilFunction.py[line:95] INFO HTTPSConnectionPool(host='www.baidu.com', port=443): Max retries exceeded with url: / (Caused by ConnectTimeoutError(<requests.packages.urllib3.connection.VerifiedHTTPSConnection object at 0x3369610>, 'Connection to 107.191.46.213 timed out. (connect timeout=40)'))
2017-06-21 14:44:27,419 utilFunction.py[line:95] INFO HTTPSConnectionPool(host='www.baidu.com', port=443): Max retries exceeded with url: / (Caused by ProxyError('Cannot connect to proxy.', error(104, 'Connection reset by peer')))
2017-06-21 14:44:34,994 utilFunction.py[line:95] INFO HTTPSConnectionPool(host='www.baidu.com', port=443): Max retries exceeded with url: / (Caused by ConnectTimeoutError(<requests.packages.urllib3.connection.VerifiedHTTPSConnection object at 0x7f7948224c90>, 'Connection to 187.84.240.162 timed out. (connect timeout=40)'))
2017-06-21 14:44:36,632 utilFunction.py[line:95] INFO HTTPSConnectionPool(host='www.baidu.com', port=443): Max retries exceeded with url: / (Caused by ProxyError('Cannot connect to proxy.', error(104, 'Connection reset by peer')))
2017-06-21 14:44:53,355 utilFunction.py[line:95] INFO HTTPSConnectionPool(host='www.baidu.com', port=443): Max retries exceeded with url: / (Caused by ConnectTimeoutError(<requests.packages.urllib3.connection.VerifiedHTTPSConnection object at 0x7f793c1c1410>, 'Connection to 156.202.50.56 timed out. (connect timeout=40)'))
2017-06-21 14:44:55,989 utilFunction.py[line:95] INFO HTTPSConnectionPool(host='www.baidu.com', port=443): Max retries exceeded with url: / (Caused by ProxyError('Cannot connect to proxy.', timeout('timed out',)))
2017-06-21 14:44:56,394 utilFunction.py[line:95] INFO HTTPSConnectionPool(host='www.baidu.com', port=443): Max retries exceeded with url: / (Caused by ConnectTimeoutError(<requests.packages.urllib3.connection.VerifiedHTTPSConnection object at 0x7f793c26f6d0>, 'Connection to 107.191.46.213 timed out. (connect timeout=40)'))
2017-06-21 14:44:57,152 utilFunction.py[line:95] INFO HTTPSConnectionPool(host='www.baidu.com', port=443): Max retries exceeded with url: / (Caused by ProxyError('Cannot connect to proxy.', timeout('timed out',)))
2017-06-21 14:44:58,948 utilFunction.py[line:95] INFO HTTPSConnectionPool(host='www.baidu.com', port=443): Max retries exceeded with url: / (Caused by ConnectTimeoutError(<requests.packages.urllib3.connection.VerifiedHTTPSConnection object at 0x7f79481eded0>, 'Connection to 156.202.50.56 timed out. (connect timeout=40)'))
2017-06-21 14:44:59,035 utilFunction.py[line:95] INFO HTTPSConnectionPool(host='www.baidu.com', port=443): Max retries exceeded with url: / (Caused by ConnectTimeoutError(<requests.packages.urllib3.connection.VerifiedHTTPSConnection object at 0x7f7940239590>, 'Connection to 156.202.50.56 timed out. (connect timeout=40)'))
2017-06-21 14:45:07,308 utilFunction.py[line:95] INFO HTTPSConnectionPool(host='www.baidu.com', port=443): Max retries exceeded with url: / (Caused by ConnectTimeoutError(<requests.packages.urllib3.connection.VerifiedHTTPSConnection object at 0x33692d0>, 'Connection to 156.202.50.56 timed out. (connect timeout=40)'))
2017-06-21 14:45:07,464 utilFunction.py[line:95] INFO HTTPSConnectionPool(host='www.baidu.com', port=443): Max retries exceeded with url: / (Caused by ConnectTimeoutError(<requests.packages.urllib3.connection.VerifiedHTTPSConnection object at 0x33697d0>, 'Connection to 107.191.46.213 timed out. (connect timeout=40)'))
2017-06-21 14:45:15,039 utilFunction.py[line:95] INFO HTTPSConnectionPool(host='www.baidu.com', port=443): Max retries exceeded with url: / (Caused by ConnectTimeoutError(<requests.packages.urllib3.connection.VerifiedHTTPSConnection object at 0x7f7948224650>, 'Connection to 107.191.46.213 timed out. (connect timeout=40)'))
2017-06-21 14:45:16,650 utilFunction.py[line:95] INFO HTTPSConnectionPool(host='www.baidu.com', port=443): Max retries exceeded with url: / (Caused by ConnectTimeoutError(<requests.packages.urllib3.connection.VerifiedHTTPSConnection object at 0x7f793c26fa10>, 'Connection to 107.191.46.213 timed out. (connect timeout=40)'))
2017-06-21 14:45:33,375 utilFunction.py[line:95] INFO HTTPSConnectionPool(host='www.baidu.com', port=443): Max retries exceeded with url: / (Caused by ConnectTimeoutError(<requests.packages.urllib3.connection.VerifiedHTTPSConnection object at 0x7f7940355550>, 'Connection to 180.158.218.58 timed out. (connect timeout=40)'))
2017-06-21 14:45:36,035 utilFunction.py[line:95] INFO HTTPSConnectionPool(host='www.baidu.com', port=443): Max retries exceeded with url: / (Caused by ConnectTimeoutError(<requests.packages.urllib3.connection.VerifiedHTTPSConnection object at 0x7f7940355710>, 'Connection to 107.191.46.213 timed out. (connect timeout=40)'))
2017-06-21 14:45:36,441 utilFunction.py[line:95] INFO HTTPSConnectionPool(host='www.baidu.com', port=443): Max retries exceeded with url: / (Caused by ConnectTimeoutError(<requests.packages.urllib3.connection.VerifiedHTTPSConnection object at 0x7f7928232790>, 'Connection to 156.202.50.56 timed out. (connect timeout=40)'))
2017-06-21 14:45:37,200 utilFunction.py[line:95] INFO HTTPSConnectionPool(host='www.baidu.com', port=443): Max retries exceeded with url: / (Caused by ConnectTimeoutError(<requests.packages.urllib3.connection.VerifiedHTTPSConnection object at 0x7f79202a9950>, 'Connection to 107.191.46.213 timed out. (connect timeout=40)'))
2017-06-21 14:45:38,959 utilFunction.py[line:95] INFO HTTPSConnectionPool(host='www.baidu.com', port=443): Max retries exceeded with url: / (Caused by ConnectTimeoutError(<requests.packages.urllib3.connection.VerifiedHTTPSConnection object at 0x7f79481ed4d0>, 'Connection to 180.158.218.58 timed out. (connect timeout=40)'))
2017-06-21 14:45:39,084 utilFunction.py[line:95] INFO HTTPSConnectionPool(host='www.baidu.com', port=443): Max retries exceeded with url: / (Caused by ConnectTimeoutError(<requests.packages.urllib3.connection.VerifiedHTTPSConnection object at 0x7f7940239610>, 'Connection to 180.158.218.58 timed out. (connect timeout=40)'))
2017-06-21 14:45:41,326 utilFunction.py[line:92] DEBUG 108.61.229.123:8080 is ok
2017-06-21 14:45:41,576 utilFunction.py[line:92] DEBUG 108.61.229.123:8080 is ok
2017-06-21 14:45:42,818 utilFunction.py[line:92] DEBUG 108.61.229.123:8080 is ok
2017-06-21 14:45:47,344 utilFunction.py[line:95] INFO HTTPSConnectionPool(host='www.baidu.com', port=443): Max retries exceeded with url: / (Caused by ConnectTimeoutError(<requests.packages.urllib3.connection.VerifiedHTTPSConnection object at 0x3369e90>, 'Connection to 180.158.218.58 timed out. (connect timeout=40)'))
2017-06-21 14:45:47,497 utilFunction.py[line:95] INFO HTTPSConnectionPool(host='www.baidu.com', port=443): Max retries exceeded with url: / (Caused by ConnectTimeoutError(<requests.packages.urllib3.connection.VerifiedHTTPSConnection object at 0x33693d0>, 'Connection to 156.202.50.56 timed out. (connect timeout=40)'))
2017-06-21 14:45:49,877 utilFunction.py[line:92] DEBUG 108.61.229.123:8080 is ok
2017-06-21 14:45:50,855 utilFunction.py[line:92] DEBUG 85.172.60.112:80 is ok
2017-06-21 14:45:55,087 utilFunction.py[line:95] INFO HTTPSConnectionPool(host='www.baidu.com', port=443): Max retries exceeded with url: / (Caused by ConnectTimeoutError(<requests.packages.urllib3.connection.VerifiedHTTPSConnection object at 0x7f7948224810>, 'Connection to 156.202.50.56 timed out. (connect timeout=40)'))
2017-06-21 14:45:56,697 utilFunction.py[line:95] INFO HTTPSConnectionPool(host='www.baidu.com', port=443): Max retries exceeded with url: / (Caused by ConnectTimeoutError(<requests.packages.urllib3.connection.VerifiedHTTPSConnection object at 0x7f793c26f790>, 'Connection to 156.202.50.56 timed out. (connect timeout=40)'))
2017-06-21 14:46:16,046 utilFunction.py[line:95] INFO HTTPSConnectionPool(host='www.baidu.com', port=443): Max retries exceeded with url: / (Caused by ConnectTimeoutError(<requests.packages.urllib3.connection.VerifiedHTTPSConnection object at 0x7f793c1c14d0>, 'Connection to 156.202.50.56 timed out. (connect timeout=40)'))
2017-06-21 14:46:16,460 utilFunction.py[line:95] INFO HTTPSConnectionPool(host='www.baidu.com', port=443): Max retries exceeded with url: / (Caused by ConnectTimeoutError(<requests.packages.urllib3.connection.VerifiedHTTPSConnection object at 0x7f793c1c10d0>, 'Connection to 180.158.218.58 timed out. (connect timeout=40)'))
2017-06-21 14:46:17,241 utilFunction.py[line:95] INFO HTTPSConnectionPool(host='www.baidu.com', port=443): Max retries exceeded with url: / (Caused by ConnectTimeoutError(<requests.packages.urllib3.connection.VerifiedHTTPSConnection object at 0x7f79202a9ad0>, 'Connection to 156.202.50.56 timed out. (connect timeout=40)'))
2017-06-21 14:46:21,610 utilFunction.py[line:95] INFO HTTPSConnectionPool(host='www.baidu.com', port=443): Max retries exceeded with url: / (Caused by ConnectTimeoutError(<requests.packages.urllib3.connection.VerifiedHTTPSConnection object at 0x7f7940239650>, 'Connection to 85.172.60.112 timed out. (connect timeout=40)'))
2017-06-21 14:46:22,712 utilFunction.py[line:95] INFO HTTPSConnectionPool(host='www.baidu.com', port=443): Max retries exceeded with url: / (Caused by ProxyError('Cannot connect to proxy.', error(104, 'Connection reset by peer')))
2017-06-21 14:46:27,534 utilFunction.py[line:95] INFO HTTPSConnectionPool(host='www.baidu.com', port=443): Max retries exceeded with url: / (Caused by ConnectTimeoutError(<requests.packages.urllib3.connection.VerifiedHTTPSConnection object at 0x3369810>, 'Connection to 180.158.218.58 timed out. (connect timeout=40)'))
2017-06-21 14:46:30,901 utilFunction.py[line:95] INFO HTTPSConnectionPool(host='www.baidu.com', port=443): Max retries exceeded with url: / (Caused by ConnectTimeoutError(<requests.packages.urllib3.connection.VerifiedHTTPSConnection object at 0x7f793c1c1750>, 'Connection to 110.73.0.60 timed out. (connect timeout=40)'))
2017-06-21 14:46:35,099 utilFunction.py[line:95] INFO HTTPSConnectionPool(host='www.baidu.com', port=443): Max retries exceeded with url: / (Caused by ConnectTimeoutError(<requests.packages.urllib3.connection.VerifiedHTTPSConnection object at 0x7f7948224350>, 'Connection to 180.158.218.58 timed out. (connect timeout=40)'))
2017-06-21 14:46:36,741 utilFunction.py[line:95] INFO HTTPSConnectionPool(host='www.baidu.com', port=443): Max retries exceeded with url: / (Caused by ConnectTimeoutError(<requests.packages.urllib3.connection.VerifiedHTTPSConnection object at 0x7f793c26f850>, 'Connection to 180.158.218.58 timed out. (connect timeout=40)'))
2017-06-21 14:46:38,603 utilFunction.py[line:95] INFO HTTPSConnectionPool(host='www.baidu.com', port=443): Max retries exceeded with url: / (Caused by ProxyError('Cannot connect to proxy.', error(104, 'Connection reset by peer')))
2017-06-21 14:46:45,713 utilFunction.py[line:95] INFO HTTPSConnectionPool(host='www.baidu.com', port=443): Max retries exceeded with url: / (Caused by ProxyError('Cannot connect to proxy.', error(104, 'Connection reset by peer')))
2017-06-21 14:46:47,376 utilFunction.py[line:92] DEBUG 85.172.60.112:80 is ok
2017-06-21 14:46:52,878 utilFunction.py[line:92] DEBUG 108.61.229.123:8080 is ok
2017-06-21 14:46:54,336 utilFunction.py[line:92] DEBUG 108.61.229.123:8080 is ok
2017-06-21 14:46:56,093 utilFunction.py[line:95] INFO HTTPSConnectionPool(host='www.baidu.com', port=443): Max retries exceeded with url: / (Caused by ConnectTimeoutError(<requests.packages.urllib3.connection.VerifiedHTTPSConnection object at 0x7f793c1c14d0>, 'Connection to 180.158.218.58 timed out. (connect timeout=40)'))
2017-06-21 14:46:57,289 utilFunction.py[line:95] INFO HTTPSConnectionPool(host='www.baidu.com', port=443): Max retries exceeded with url: / (Caused by ConnectTimeoutError(<requests.packages.urllib3.connection.VerifiedHTTPSConnection object at 0x7f79202a9b10>, 'Connection to 180.158.218.58 timed out. (connect timeout=40)'))
2017-06-21 14:46:59,018 utilFunction.py[line:92] DEBUG 108.61.229.123:8080 is ok
2017-06-21 14:47:00,257 utilFunction.py[line:92] DEBUG 108.61.229.123:8080 is ok
2017-06-21 14:47:01,016 utilFunction.py[line:92] DEBUG 108.61.229.123:8080 is ok
2017-06-21 14:47:01,628 utilFunction.py[line:95] INFO HTTPSConnectionPool(host='www.baidu.com', port=443): Max retries exceeded with url: / (Caused by ConnectTimeoutError(<requests.packages.urllib3.connection.VerifiedHTTPSConnection object at 0x7f79401bcf10>, 'Connection to 110.73.0.60 timed out. (connect timeout=40)'))
2017-06-21 14:47:02,758 utilFunction.py[line:95] INFO HTTPSConnectionPool(host='www.baidu.com', port=443): Max retries exceeded with url: / (Caused by ConnectTimeoutError(<requests.packages.urllib3.connection.VerifiedHTTPSConnection object at 0x3369050>, 'Connection to 110.73.0.60 timed out. (connect timeout=40)'))
2017-06-21 14:47:02,947 utilFunction.py[line:92] DEBUG 85.172.60.112:80 is ok
2017-06-21 14:47:04,636 utilFunction.py[line:92] DEBUG 85.172.60.112:80 is ok
2017-06-21 14:47:06,606 utilFunction.py[line:92] DEBUG 85.172.60.112:80 is ok
2017-06-21 14:47:09,872 utilFunction.py[line:92] DEBUG 85.172.60.112:80 is ok
2017-06-21 14:47:10,949 utilFunction.py[line:95] INFO HTTPSConnectionPool(host='www.baidu.com', port=443): Max retries exceeded with url: / (Caused by ConnectTimeoutError(<requests.packages.urllib3.connection.VerifiedHTTPSConnection object at 0x7f793c1c1810>, 'Connection to 89.38.150.214 timed out. (connect timeout=40)'))
2017-06-21 14:47:25,761 utilFunction.py[line:95] INFO HTTPSConnectionPool(host='www.baidu.com', port=443): Max retries exceeded with url: / (Caused by ConnectTimeoutError(<requests.packages.urllib3.connection.VerifiedHTTPSConnection object at 0x7f793c1c1310>, 'Connection to 110.73.0.60 timed out. (connect timeout=40)'))
2017-06-21 14:47:27,417 utilFunction.py[line:95] INFO HTTPSConnectionPool(host='www.baidu.com', port=443): Max retries exceeded with url: / (Caused by ConnectTimeoutError(<requests.packages.urllib3.connection.VerifiedHTTPSConnection object at 0x7f793c1c1c10>, 'Connection to 110.73.0.60 timed out. (connect timeout=40)'))
2017-06-21 14:47:30,482 utilFunction.py[line:95] INFO HTTPSConnectionPool(host='www.baidu.com', port=443): Max retries exceeded with url: / (Caused by ProxyError('Cannot connect to proxy.', error(104, 'Connection reset by peer')))
2017-06-21 14:47:41,670 utilFunction.py[line:95] INFO HTTPSConnectionPool(host='www.baidu.com', port=443): Max retries exceeded with url: / (Caused by ConnectTimeoutError(<requests.packages.urllib3.connection.VerifiedHTTPSConnection object at 0x7f793c26f2d0>, 'Connection to 89.38.150.214 timed out. (connect timeout=40)'))
2017-06-21 14:47:42,799 utilFunction.py[line:95] INFO HTTPSConnectionPool(host='www.baidu.com', port=443): Max retries exceeded with url: / (Caused by ConnectTimeoutError(<requests.packages.urllib3.connection.VerifiedHTTPSConnection object at 0x3369090>, 'Connection to 89.38.150.214 timed out. (connect timeout=40)'))
2017-06-21 14:47:42,954 utilFunction.py[line:95] INFO HTTPSConnectionPool(host='www.baidu.com', port=443): Max retries exceeded with url: / (Caused by ConnectTimeoutError(<requests.packages.urllib3.connection.VerifiedHTTPSConnection object at 0x7f7948224510>, 'Connection to 110.73.0.60 timed out. (connect timeout=40)'))
2017-06-21 14:47:44,683 utilFunction.py[line:95] INFO HTTPSConnectionPool(host='www.baidu.com', port=443): Max retries exceeded with url: / (Caused by ConnectTimeoutError(<requests.packages.urllib3.connection.VerifiedHTTPSConnection object at 0x7f793c26f550>, 'Connection to 110.73.0.60 timed out. (connect timeout=40)'))
2017-06-21 14:47:46,627 utilFunction.py[line:95] INFO HTTPSConnectionPool(host='www.baidu.com', port=443): Max retries exceeded with url: / (Caused by ConnectTimeoutError(<requests.packages.urllib3.connection.VerifiedHTTPSConnection object at 0x3369a50>, 'Connection to 110.73.0.60 timed out. (connect timeout=40)'))
2017-06-21 14:47:49,889 utilFunction.py[line:95] INFO HTTPSConnectionPool(host='www.baidu.com', port=443): Max retries exceeded with url: / (Caused by ConnectTimeoutError(<requests.packages.urllib3.connection.VerifiedHTTPSConnection object at 0x7f7940239310>, 'Connection to 110.73.0.60 timed out. (connect timeout=40)'))
2017-06-21 14:47:50,998 utilFunction.py[line:95] INFO HTTPSConnectionPool(host='www.baidu.com', port=443): Max retries exceeded with url: / (Caused by ConnectTimeoutError(<requests.packages.urllib3.connection.VerifiedHTTPSConnection object at 0x7f793c1c1750>, 'Connection to 49.213.17.179 timed out. (connect timeout=40)'))
2017-06-21 14:48:05,807 utilFunction.py[line:95] INFO HTTPSConnectionPool(host='www.baidu.com', port=443): Max retries exceeded with url: / (Caused by ConnectTimeoutError(<requests.packages.urllib3.connection.VerifiedHTTPSConnection object at 0x7f793c1c1a50>, 'Connection to 89.38.150.214 timed out. (connect timeout=40)'))
2017-06-21 14:48:07,463 utilFunction.py[line:95] INFO HTTPSConnectionPool(host='www.baidu.com', port=443): Max retries exceeded with url: / (Caused by ConnectTimeoutError(<requests.packages.urllib3.connection.VerifiedHTTPSConnection object at 0x7f793c1c1c10>, 'Connection to 89.38.150.214 timed out. (connect timeout=40)'))
2017-06-21 14:48:10,498 utilFunction.py[line:95] INFO HTTPSConnectionPool(host='www.baidu.com', port=443): Max retries exceeded with url: / (Caused by ConnectTimeoutError(<requests.packages.urllib3.connection.VerifiedHTTPSConnection object at 0x7f79202a9a90>, 'Connection to 110.73.0.60 timed out. (connect timeout=40)'))
2017-06-21 14:48:21,716 utilFunction.py[line:95] INFO HTTPSConnectionPool(host='www.baidu.com', port=443): Max retries exceeded with url: / (Caused by ConnectTimeoutError(<requests.packages.urllib3.connection.VerifiedHTTPSConnection object at 0x7f793c26f190>, 'Connection to 49.213.17.179 timed out. (connect timeout=40)'))
2017-06-21 14:48:22,835 utilFunction.py[line:95] INFO HTTPSConnectionPool(host='www.baidu.com', port=443): Max retries exceeded with url: / (Caused by ConnectTimeoutError(<requests.packages.urllib3.connection.VerifiedHTTPSConnection object at 0x33691d0>, 'Connection to 49.213.17.179 timed out. (connect timeout=40)'))
2017-06-21 14:48:22,979 utilFunction.py[line:95] INFO HTTPSConnectionPool(host='www.baidu.com', port=443): Max retries exceeded with url: / (Caused by ConnectTimeoutError(<requests.packages.urllib3.connection.VerifiedHTTPSConnection object at 0x7f7948224550>, 'Connection to 89.38.150.214 timed out. (connect timeout=40)'))
2017-06-21 14:48:24,729 utilFunction.py[line:95] INFO HTTPSConnectionPool(host='www.baidu.com', port=443): Max retries exceeded with url: / (Caused by ConnectTimeoutError(<requests.packages.urllib3.connection.VerifiedHTTPSConnection object at 0x7f793c26f990>, 'Connection to 89.38.150.214 timed out. (connect timeout=40)'))
2017-06-21 14:48:26,638 utilFunction.py[line:95] INFO HTTPSConnectionPool(host='www.baidu.com', port=443): Max retries exceeded with url: / (Caused by ConnectTimeoutError(<requests.packages.urllib3.connection.VerifiedHTTPSConnection object at 0x7f79402392d0>, 'Connection to 89.38.150.214 timed out. (connect timeout=40)'))
2017-06-21 14:48:29,899 utilFunction.py[line:95] INFO HTTPSConnectionPool(host='www.baidu.com', port=443): Max retries exceeded with url: / (Caused by ConnectTimeoutError(<requests.packages.urllib3.connection.VerifiedHTTPSConnection object at 0x7f79402394d0>, 'Connection to 89.38.150.214 timed out. (connect timeout=40)'))
2017-06-21 14:48:31,045 utilFunction.py[line:95] INFO HTTPSConnectionPool(host='www.baidu.com', port=443): Max retries exceeded with url: / (Caused by ConnectTimeoutError(<requests.packages.urllib3.connection.VerifiedHTTPSConnection object at 0x7f793c1c1910>, 'Connection to 45.32.150.160 timed out. (connect timeout=40)'))
2017-06-21 14:48:34,248 utilFunction.py[line:92] DEBUG 94.177.240.99:1189 is ok
2017-06-21 14:48:45,849 utilFunction.py[line:95] INFO HTTPSConnectionPool(host='www.baidu.com', port=443): Max retries exceeded with url: / (Caused by ConnectTimeoutError(<requests.packages.urllib3.connection.VerifiedHTTPSConnection object at 0x7f7948224b90>, 'Connection to 49.213.17.179 timed out. (connect timeout=40)'))
2017-06-21 14:48:47,499 utilFunction.py[line:95] INFO HTTPSConnectionPool(host='www.baidu.com', port=443): Max retries exceeded with url: / (Caused by ConnectTimeoutError(<requests.packages.urllib3.connection.VerifiedHTTPSConnection object at 0x7f7928232710>, 'Connection to 49.213.17.179 timed out. (connect timeout=40)'))
2017-06-21 14:48:50,525 utilFunction.py[line:95] INFO HTTPSConnectionPool(host='www.baidu.com', port=443): Max retries exceeded with url: / (Caused by ConnectTimeoutError(<requests.packages.urllib3.connection.VerifiedHTTPSConnection object at 0x7f79202a9b10>, 'Connection to 89.38.150.214 timed out. (connect timeout=40)'))
2017-06-21 14:49:01,761 utilFunction.py[line:95] INFO HTTPSConnectionPool(host='www.baidu.com', port=443): Max retries exceeded with url: / (Caused by ConnectTimeoutError(<requests.packages.urllib3.connection.VerifiedHTTPSConnection object at 0x7f793c26f390>, 'Connection to 45.32.150.160 timed out. (connect timeout=40)'))
2017-06-21 14:49:02,882 utilFunction.py[line:95] INFO HTTPSConnectionPool(host='www.baidu.com', port=443): Max retries exceeded with url: / (Caused by ConnectTimeoutError(<requests.packages.urllib3.connection.VerifiedHTTPSConnection object at 0x3369350>, 'Connection to 45.32.150.160 timed out. (connect timeout=40)'))
2017-06-21 14:49:03,017 utilFunction.py[line:95] INFO HTTPSConnectionPool(host='www.baidu.com', port=443): Max retries exceeded with url: / (Caused by ConnectTimeoutError(<requests.packages.urllib3.connection.VerifiedHTTPSConnection object at 0x7f7948224810>, 'Connection to 49.213.17.179 timed out. (connect timeout=40)'))
2017-06-21 14:49:04,776 utilFunction.py[line:95] INFO HTTPSConnectionPool(host='www.baidu.com', port=443): Max retries exceeded with url: / (Caused by ConnectTimeoutError(<requests.packages.urllib3.connection.VerifiedHTTPSConnection object at 0x7f793c26f550>, 'Connection to 49.213.17.179 timed out. (connect timeout=40)'))
2017-06-21 14:49:06,038 utilFunction.py[line:92] DEBUG 94.177.240.99:1189 is ok
2017-06-21 14:49:06,524 utilFunction.py[line:92] DEBUG 94.177.240.99:1189 is ok
2017-06-21 14:49:06,681 utilFunction.py[line:95] INFO HTTPSConnectionPool(host='www.baidu.com', port=443): Max retries exceeded with url: / (Caused by ConnectTimeoutError(<requests.packages.urllib3.connection.VerifiedHTTPSConnection object at 0x3369a50>, 'Connection to 49.213.17.179 timed out. (connect timeout=40)'))
2017-06-21 14:49:09,907 utilFunction.py[line:95] INFO HTTPSConnectionPool(host='www.baidu.com', port=443): Max retries exceeded with url: / (Caused by ConnectTimeoutError(<requests.packages.urllib3.connection.VerifiedHTTPSConnection object at 0x7f7940239310>, 'Connection to 49.213.17.179 timed out. (connect timeout=40)'))
2017-06-21 14:49:14,283 utilFunction.py[line:95] INFO HTTPSConnectionPool(host='www.baidu.com', port=443): Max retries exceeded with url: / (Caused by ConnectTimeoutError(<requests.packages.urllib3.connection.VerifiedHTTPSConnection object at 0x7f79481ed990>, 'Connection to 125.105.19.177 timed out. (connect timeout=40)'))
2017-06-21 14:49:25,888 utilFunction.py[line:95] INFO HTTPSConnectionPool(host='www.baidu.com', port=443): Max retries exceeded with url: / (Caused by ConnectTimeoutError(<requests.packages.urllib3.connection.VerifiedHTTPSConnection object at 0x7f7940355650>, 'Connection to 45.32.150.160 timed out. (connect timeout=40)'))
2017-06-21 14:49:27,522 utilFunction.py[line:95] INFO HTTPSConnectionPool(host='www.baidu.com', port=443): Max retries exceeded with url: / (Caused by ConnectTimeoutError(<requests.packages.urllib3.connection.VerifiedHTTPSConnection object at 0x7f7928232850>, 'Connection to 45.32.150.160 timed out. (connect timeout=40)'))
2017-06-21 14:49:29,435 utilFunction.py[line:92] DEBUG 94.177.240.99:1189 is ok
2017-06-21 14:49:30,573 utilFunction.py[line:95] INFO HTTPSConnectionPool(host='www.baidu.com', port=443): Max retries exceeded with url: / (Caused by ConnectTimeoutError(<requests.packages.urllib3.connection.VerifiedHTTPSConnection object at 0x7f7940355350>, 'Connection to 49.213.17.179 timed out. (connect timeout=40)'))
2017-06-21 14:49:30,628 utilFunction.py[line:92] DEBUG 94.177.240.99:1189 is ok
2017-06-21 14:49:43,065 utilFunction.py[line:95] INFO HTTPSConnectionPool(host='www.baidu.com', port=443): Max retries exceeded with url: / (Caused by ConnectTimeoutError(<requests.packages.urllib3.connection.VerifiedHTTPSConnection object at 0x7f7948224c90>, 'Connection to 45.32.150.160 timed out. (connect timeout=40)'))
2017-06-21 14:49:44,821 utilFunction.py[line:95] INFO HTTPSConnectionPool(host='www.baidu.com', port=443): Max retries exceeded with url: / (Caused by ConnectTimeoutError(<requests.packages.urllib3.connection.VerifiedHTTPSConnection object at 0x7f793c26f790>, 'Connection to 45.32.150.160 timed out. (connect timeout=40)'))
2017-06-21 14:49:46,059 utilFunction.py[line:95] INFO HTTPSConnectionPool(host='www.baidu.com', port=443): Max retries exceeded with url: / (Caused by ConnectTimeoutError(<requests.packages.urllib3.connection.VerifiedHTTPSConnection object at 0x3369310>, 'Connection to 125.105.19.177 timed out. (connect timeout=40)'))
2017-06-21 14:49:46,305 utilFunction.py[line:92] DEBUG 94.177.240.99:1189 is ok
2017-06-21 14:49:46,562 utilFunction.py[line:95] INFO HTTPSConnectionPool(host='www.baidu.com', port=443): Max retries exceeded with url: / (Caused by ConnectTimeoutError(<requests.packages.urllib3.connection.VerifiedHTTPSConnection object at 0x7f793c26f250>, 'Connection to 125.105.19.177 timed out. (connect timeout=40)'))
2017-06-21 14:49:46,723 utilFunction.py[line:95] INFO HTTPSConnectionPool(host='www.baidu.com', port=443): Max retries exceeded with url: / (Caused by ConnectTimeoutError(<requests.packages.urllib3.connection.VerifiedHTTPSConnection object at 0x7f79402392d0>, 'Connection to 45.32.150.160 timed out. (connect timeout=40)'))
2017-06-21 14:49:47,975 utilFunction.py[line:92] DEBUG 94.177.240.99:1189 is ok
2017-06-21 14:49:49,953 utilFunction.py[line:95] INFO HTTPSConnectionPool(host='www.baidu.com', port=443): Max retries exceeded with url: / (Caused by ConnectTimeoutError(<requests.packages.urllib3.connection.VerifiedHTTPSConnection object at 0x7f793c26ff50>, 'Connection to 45.32.150.160 timed out. (connect timeout=40)'))
2017-06-21 14:49:50,055 utilFunction.py[line:92] DEBUG 94.177.240.99:1189 is ok
2017-06-21 14:49:53,142 utilFunction.py[line:92] DEBUG 94.177.240.99:1189 is ok
2017-06-21 14:49:54,315 utilFunction.py[line:95] INFO HTTPSConnectionPool(host='www.baidu.com', port=443): Max retries exceeded with url: / (Caused by ConnectTimeoutError(<requests.packages.urllib3.connection.VerifiedHTTPSConnection object at 0x7f793c26f2d0>, 'Connection to 201.219.176.117 timed out. (connect timeout=40)'))
